<?xml version="1.0"?>

<robot name="trunk" xmlns:xacro="http://ros.org/wiki/xacro">
	
  <xacro:include filename="$(find crom2_description)/urdf/gazebo/crom2_trunk.gazebo.xacro" />

  <!-- Define a number of dimensions using properties -->
  <property name="trunk_size_x" value="0.45" />
  <property name="trunk_size_y" value="0.284" />
  <property name="trunk_size_z" value="0.545" />
       
  <!-- Define the trunk -->
  <xacro:macro name="trunk_model" params="parent name color *origin">
    <joint name="${name}_joint" type="revolute">
		<xacro:insert_block name="origin" />
		<parent link="${parent}_link" />
		<child link="${name}_link" />
		<axis xyz="0 0 1" />
		<limit effort="1.5" velocity="1.0" lower="${reverse*M_PI/2}" upper="${M_PI/2}" />
	</joint>
    
	<link name="${name}_link">
		<inertial>
		  <mass value="22.07245" />
		  <origin xyz="0 0 0" />
		  <inertia  ixx="1259.328" ixy="-0.695"  ixz="15.497"  iyy="934.927"  iyz="-0.007"  izz="771.083" />
		</inertial>
      <visual>
        <origin xyz="0 0 0" rpy="0 0 0" />
        <geometry>
          <mesh filename = "package://crom2_description/meshes/CROM2_trunk.STL"/>
        </geometry>
        <material name="${color}" />
      </visual>
      <collision>
        <origin xyz="0 0 0" rpy="0 0 0" />
        <geometry>
		  <mesh filename = "package://crom2_description/meshes/CROM2_trunk.dae"/>
        </geometry>
      </collision>
    </link>
    
    <!--Add trunk_gazebo macro -->
	<trunk_gazebo name="${name}" />
	
  </xacro:macro>

</robot>
			

